Traceback (most recent call last):
  File "C:\Users\lucas\miniforge3\Lib\site-packages\jupyter_cache\executors\utils.py", line 58, in single_nb_execution
    executenb(
  File "C:\Users\lucas\miniforge3\Lib\site-packages\nbclient\client.py", line 1319, in execute
    return NotebookClient(nb=nb, resources=resources, km=km, **kwargs).execute()
           ^^^^^^^^^^^^^^^^^^^^^^^^^^^^^^^^^^^^^^^^^^^^^^^^^^^^^^^^^^^^^^^^^^^^^
  File "C:\Users\lucas\miniforge3\Lib\site-packages\jupyter_core\utils\__init__.py", line 165, in wrapped
    return loop.run_until_complete(inner)
           ^^^^^^^^^^^^^^^^^^^^^^^^^^^^^^
  File "C:\Users\lucas\miniforge3\Lib\asyncio\base_events.py", line 691, in run_until_complete
    return future.result()
           ^^^^^^^^^^^^^^^
  File "C:\Users\lucas\miniforge3\Lib\site-packages\nbclient\client.py", line 709, in async_execute
    await self.async_execute_cell(
  File "C:\Users\lucas\miniforge3\Lib\site-packages\nbclient\client.py", line 1062, in async_execute_cell
    await self._check_raise_for_error(cell, cell_index, exec_reply)
  File "C:\Users\lucas\miniforge3\Lib\site-packages\nbclient\client.py", line 918, in _check_raise_for_error
    raise CellExecutionError.from_cell_and_msg(cell, exec_reply_content)
nbclient.exceptions.CellExecutionError: An error occurred while executing the following cell:
------------------
from ase.build import bulk
from ase.visualize.plot import plot_atoms
import matplotlib.pyplot as plt

metal = bulk('Pt', crystalstructure='fcc', a=4.00)

fig = plt.figure(figsize=(3, 3))
ax = fig.add_subplot()
plot_atoms(metal.repeat((5, 5, 3)), ax)
plt.axis('off')
plt.show()
------------------


[31m---------------------------------------------------------------------------[39m
[31mModuleNotFoundError[39m                       Traceback (most recent call last)
[36mCell[39m[36m [39m[32mIn[1][39m[32m, line 1[39m
[32m----> [39m[32m1[39m [38;5;28;01mfrom[39;00m[38;5;250m [39m[34;01mase[39;00m[34;01m.[39;00m[34;01mbuild[39;00m[38;5;250m [39m[38;5;28;01mimport[39;00m bulk
[32m      2[39m [38;5;28;01mfrom[39;00m[38;5;250m [39m[34;01mase[39;00m[34;01m.[39;00m[34;01mvisualize[39;00m[34;01m.[39;00m[34;01mplot[39;00m[38;5;250m [39m[38;5;28;01mimport[39;00m plot_atoms
[32m      3[39m [38;5;28;01mimport[39;00m[38;5;250m [39m[34;01mmatplotlib[39;00m[34;01m.[39;00m[34;01mpyplot[39;00m[38;5;250m [39m[38;5;28;01mas[39;00m[38;5;250m [39m[34;01mplt[39;00m

[31mModuleNotFoundError[39m: No module named 'ase'

